Workbook

Sheet Overview
B2: ERDR Algorithm — Enemy-Radius Density Reduction
B3: Heart-Disease (7, 13, 2) selected from Heart-Disease (270, 13, 2) · Zhuravlev metric · k = 3 · article §1.1 (N. A. Ignatev) · training / validation split for the ensemble experiments
B5: Workbook map
B6: # | C6: Sheet | D6: Stage | E6: What it contains
B7: 1 | C7: Parameters | D7: 0 · Parameters | E7: N and class sizes, the k rule (k_min = 3, k_max = 2·min|Kᵢ| − 3), k for z(Sᵢ, k), ε, the three reading switches A, B, C, metric and ERDR definitions.
B8: 2 | C8: Object Selection | D8: 0 · Sample choice | E8: Why N = 7: lower bound from the k rule, search evidence over the 270 objects, the chosen rows and why this subset.
B9: 3 | C9: Source Dataset (270) | D9: 1 · Input data | E9: All 270 objects × 13 features with classes and type flags; the 7 selected objects are highlighted.
B10: 4 | C10: Dataset | D10: 1 · Input data | E10: The 7 selected objects S₁ … S₇ (source rows are input cells) with quantitative and nominal views.
B11: 5 | C11: Normalized Dataset | D11: Step 0 · Scale unification | E11: Quantitative features rescaled to [0, 1] over the 7 objects; nominal codes unchanged; type, min, max.
B12: 6 | C12: Zhuravlev Distances | D12: Step 0 · Distances | E12: Zhuravlev distance ρ = ρ_I + ρ_J for every pair, with both parts.
B13: 7 | C13: Sorted Neighbors | D13: Step 0 · Neighbours | E13: Rank matrix and one block per object: nearest enemy (r), k-th neighbour (z), own-class objects inside the enemy sphere (g).
B14: 8 | C14: ERDR Characteristics | D14: Step 1 · r, g, z, d | E14: The four auxiliary functions per object, the Step 2 priority position, and the enemy-sphere membership matrix.
B15: 9 | C15: Hyperspheres (Step 1) | D15: Step 1 · Hyperspheres | E15: Per object: the enemy sphere (Sᵢ, r) and its g members, the k-sphere (Sᵢ, z), d as the gap between the two radii; neighbourhood strips, the radius plane and one sphere diagram per object.
B16: 10 | C16: Priority Queue | D16: Step 2 · Queue | E16: Static queue order by d → r → index, with the criterion that decided every adjacent pair.
B17: 11 | C17: ERDR Iterations | D17: Steps 2–5 · Iterations | E17: One block per iteration: queue, selected Sᵢ, the set L, blocking, the Step 4 / Step 5 decision and the counter corrections.
B18: 12 | C18: Hyperspheres (Iterations) | D18: Steps 2–5 · Hyperspheres | E18: Per iteration: the enemy spheres of the own-class objects drawn around the selected Sᵢ — the spheres that contain Sᵢ form L; counters and moves to D.
... B27: 21 | C27: Hypersphere Data | D27: Visualisation · data | E27: Coordinates of the hypersphere diagrams (live formulas): radial positions, sphere outlines, strips and the radius plane.
B29: Algorithm — pipeline specification (article element → sheet → Python function)
B30: # | C30: Article element | D30: Sheet | E30: Definition → Python function (erdrlab)
B31: 1 | C31: Data, feature types, classes | D31: Dataset | E31: E₀ = the 7 selected objects of the 270, X(n) heterogeneous, K1, K2 → data.load_csv(path) → (X, y, types)
B32: 2 | C32: Scale unification | D32: Normalized Dataset | E32: x′ = (x − min)/(max − min) for type 1 over the selected objects → metric.scale_params, metric.unify
B33: 3 | C33: Zhuravlev metric | D33: Zhuravlev Distances | E33: ρ = Σ(I) |x′ − y′| + Σ(J) [x ≠ y], 10-decimal rounding → metric.zhuravlev, metric.distance_matrix
B34: 4 | C34: Step 1 · r, g, z, d | D34: ERDR Characteristics | E34: nearest-enemy radius, own-class count inside it, k-th neighbour distance, priority → erdr.characteristics(D, y, k)
B35: 5 | C35: Step 2 · queue | D35: Priority Queue | E35: order by (d, r, index) over F with d ≥ 0 → inside erdr.run
B36: 6 | C36: Steps 3–5 · iterations | D36: ERDR Iterations | E36: select Sᵢ, build L, block Sᵢ, |L| = 1 → D, |L| > 1 → g − 1 and moves → erdr.run(D, y, k, ε, self_in_L, blocked_cover, step5)
B37: 7 | C37: Step 6 · output | D37: Training & Validation | E37: D = training sample, F = E₀ \ D = validation sample → erdr.run(...)["D"], ["F"]
B38: 8 | C38: Cases | D38: Case Checklist | E38: 17 cases of the algorithm detected from the trace → cases.detect(result, D, y)
B39: 9 | C39: Validation | D39: Validation | E39: workbook vs engine → tests with the golden values of this workbook
B41: Key results (live)
B42: # | C42: Figure | D42: Value | E42: Linked to
B43: 1 | C43: Objects N · |K1| · |K2| | D43: ='Parameters'!$B$5&" · "&'Parameters'!$B$6&" · "&'Parameters'!$B$7 -> 7 · 3 · 4 | E43: Parameters
B44: 2 | C44: k used for z(Sᵢ, k) · k rule 3 … 2·min|Kᵢ| − 3 | D44: ='Parameters'!$B$12&" (permitted: "&'Parameters'!$B$11&")" -> 3 (permitted: 3) | E44: Parameters
B45: 3 | C45: Step 2 queue order | D45: ='Validation'!C34 -> S₁ → S₃ → S₅ → S₂ → S₇ → S₆ → S₄ | E45: Priority Queue
B46: 4 | C46: Iterations until the queue is empty | D46: =COUNTIF('ERDR Trace'!B5:B11,"S*") -> 6 | E46: ERDR Trace
B47: 5 | C47: Training sample D | D47: ='Training & Validation'!B19&" · "&'Training & Validation'!D15&" (K1 "&'Training & Validation'!B15&", K2 "&'Training & Validation'!C15&")" -> {S₁, S₂, S₅, S₆, S₇} · 5 (K1 2, K2 3) | E47: Training & Validation
B48: 6 | C48: Validation sample F | D48: ='Training & Validation'!B20&" · "&'Training & Validation'!D16&" (K1 "&'Training & Validation'!B16&", K2 "&'Training & Validation'!C16&")" -> {S₃, S₄} · 2 (K1 1, K2 1) | E48: Training & Validation
B49: 7 | C49: Share of N in the training sample | D49: ='Training & Validation'!E15 -> 0.71428571 | E49: Training & Validation
B50: 8 | C50: Cases of the algorithm that occur | D50: =SUM('Case Checklist'!D5:D21)&" of 17" -> 17 of 17 | E50: Case Checklist
B51: 9 | C51: Reading | D51: ='Parameters'!B27 -> ✓ literal article reading (default) | E51: Readings (Switches)
B52: 10 | C52: Validation checks | D52: ='Validation'!B59 -> 53 of 53 checks pass ✓ | E52: Validation
...

Sheet Parameters
A1: Experiment parameters — every ERDR stage reads its settings from this sheet
A3: Sample and k range · k_min = 3 fixed, k_max = 2 · min |Kᵢ| − 3 from the class sizes (the same rule as in our other experiments)
A4: Parameter | B4: Value | C4: Rule / meaning
A5: N (objects in the experiment) | B5: =COUNT('Dataset'!B5:B11) -> 7 | C5: Selected rows of the 270-object source (Dataset sheet) — why 7: see “Object Selection”
A6: |K1| (objects of class 1) | B6: =COUNTIF('Dataset'!P5:P11,1) -> 3 | C6: Counted from the class column — never typed in
A7: |K2| (objects of class 2) | B7: =COUNTIF('Dataset'!P5:P11,2) -> 4
A8: min |Kᵢ| | B8: =MIN(B6,B7) -> 3 | C8: Smallest class
A9: k_min | B9: 3 | C9: Fixed for every dataset
A10: k_max = 2 · min |Kᵢ| − 3 | B10: =2*B8-3 -> 3 | C10: Largest permitted k
A11: Permitted k (odd, k_min … k_max) | B11: =IF(B10<B9,"none — a class has fewer than 3 objects",IF(B10>=5,"3, 5, …, "&B10,"3")) -> 3
A12: k used by ERDR in z(Sᵢ, k) | B12: 3 | C12: Input · the k-th nearest neighbour gives z(Sᵢ, k); must be permitted and ≤ N − 1
A13: k check | B13: =IF(MIN(B6,B7)=0,"⚠ the selection has only one class — ERDR needs both",IF(AND(B12>=B9,B12<=B10,MOD(B12-B9,2)=0,B12<=B5-1),"✓ k is permitted by the rule","⚠ k is outside the permitted range "&B11)) -> ✓ k is permitted by the rule
A15: ERDR constants (article §1.1)
A16: Parameter | B16: Value | C16: Rule / meaning
A17: ε (blocking constant, ε > 0) | B17: 0.001 | C17: Step 4 blocks the selected object by d(Sᵢ) ← −(d(Sᵢ) + ε); any ε > 0 gives the same result
A18: Distance rounding | B18: 10 decimals | C18: Mathematically equal distances and d values tie exactly
A19: Queue order (Step 2) | B19: d → r → index | C19: Ascending d(Sᵢ); equal d → ascending r(Sᵢ); equal d and r → ascending index
A20: Iteration blocks | B20: =B5 -> 7 | C20: Every iteration processes (blocks) one queue object, so at most N iterations are needed
A22: Readings of three points the article leaves open · 1 = literal article text (default), 2 = alternative · see “Readings (Switches)”
A23: Parameter | B23: Value | C23: Rule / meaning
A24: A · Sᵢ itself can be a member of L | B24: 1 | C24: 1 = literal: Sᵢ ∈ L whenever g(Sᵢ) > 1 (ρ(Sᵢ, Sᵢ) = 0 < r(Sᵢ)) · 2 = only other objects form L
A25: B · processed objects keep covering | B25: 1 | C25: 1 = literal: blocked objects stay in F and can belong to L later · 2 = only objects still in the queue can belong to L
A26: C · return to Step 2 in Step 5 | B26: 1 | C26: 1 = after the whole set L has been corrected · 2 = right after the first object whose g falls to 1 (members of L taken by ascending index)
A27: Reading status | B27: =IF(AND(B24=1,B25=1,B26=1),"✓ literal article reading (default)","⚠ alternative reading "&B24&B25&B26&" — compare with Readings (Switches)") -> ✓ literal article reading (default)
A29: Metric · Zhuravlev metric on heterogeneous features (quantitative features rescaled to [0, 1])
A30: Operator | B30: Feature set | C30: Definition
A31: ρ | B31: all 13 (I ∪ J) | C31: ρ(x, y) = Σ(j∈I) |x′ⱼ − y′ⱼ| + Σ(j∈J) [xⱼ ≠ yⱼ] (x′ = (x − min)/(max − min) over the N objects)
A32: ρ_I | B32: 6 quantitative (I) | C32: ρ_I(x, y) = Σ(j∈I) |x′ⱼ − y′ⱼ| — quantitative part
A33: ρ_J | B33: 7 nominal (J) | C33: ρ_J(x, y) = Σ(j∈J) [xⱼ ≠ yⱼ] — nominal part (number of different codes)
A35: ERDR definitions (article §1.1) · Sᵢ ∈ K_t
A36: Symbol | B36: Sheet | C36: Definition
A37: r(Sᵢ) | B37: ERDR Characteristics | C37: distance from Sᵢ to the nearest object of the other class (enemy radius)
A38: g(Sᵢ) | B38: ERDR Characteristics | C38: number of objects of K_t strictly inside the sphere (Sᵢ, r(Sᵢ)); Sᵢ itself counts, so g ≥ 1
A39: z(Sᵢ, k) | B39: ERDR Characteristics | C39: distance from Sᵢ to its k-th nearest neighbour (all objects, Sᵢ excluded)
A40: d(Sᵢ) | B40: ERDR Characteristics | C40: |z(Sᵢ, k) − r(Sᵢ)| / (z(Sᵢ, k) + r(Sᵢ)) — priority of Sᵢ (smaller = earlier)
A41: Queue | B41: Priority Queue | C41: {Sᵢ ∈ F | d(Sᵢ) ≥ 0} ordered by d → r → index; empty queue → Step 6
A42: L | B42: ERDR Iterations | C42: {Sⱼ ∈ F ∩ K_t | ρ(Sⱼ, Sᵢ) < r(Sⱼ) and g(Sⱼ) > 1}: objects whose enemy sphere contains Sᵢ
A43: Step 4 / 5 | B43: ERDR Iterations | C43: |L| = 1 → Sᵢ moves to D; |L| > 1 → g(Sⱼ) − 1 for Sⱼ ∈ L, and Sⱼ moves to D when g(Sⱼ) = 1
A44: Step 6 | B44: Training & Validation | C44: D = training sample, F = E₀ \ D = validation sample

Sheet Object Selection
A1: Object selection · why N = 7: the smallest sample of Heart-Disease (270, 13, 2) in which every case of the ERDR algorithm occurs
A3: Rule used
A4: 1. The sample must satisfy the k rule of our experiments: k_min = 3 must be permitted, i.e. k_max = 2·min|Kᵢ| − 3 ≥ 3, so each class needs at least 3 objects → N ≥ 6.
A5: 2. ERDR must show every case listed on the Case Checklist (17 cases: 14 branch cases of Steps 1–6 plus the index tie of Step 2, two moves in one Step 5 and a two-class validation set).
A6: 3. Among the samples that satisfy 1–2, use the smallest N; more objects only when no smaller sample shows every case.
A8: Search evidence (Python engine, literal reading, k = 3, normalisation over the selected objects)
A9: N | B9: Subsets examined | C9: Show the 14 branch cases | D9: … and case 5 (index tie) | E9: … and case 17 (two-class F) | F9: Show all 17 cases | G9: Conclusion
A10: 6 | B10: 1,594,722 | C10: 13,821 | D10: 0 | E10: 0 | F10: 0 | G10: 6 objects show the 14 branch cases, but never the index tie or a two-class validation set
A11: 7 | B11: local search, 5 min | C11: — | D11: — | E11: — | F11: 403 found | G11: N = 7 is the smallest sample with every case
A13: Chosen objects (live)
A14: № | B14: Source row | C14: Class | D14: Also in Heart-Disease (10, 13, 2) as | E14: Sample (live) | F14: Processed in iteration | G14: Case at processing
A15: S₁ | B15: ='Dataset'!B5 -> 1 | C15: ='Dataset'!P5 -> 2 | D15: =IF('Dataset'!B5=1,"S₁",IF('Dataset'!B5=10,"S₁₀",IF('Dataset'!B5<=10,"S"&'Dataset'!B5,"—"))) -> S₁ | E15: ='Training & Validation'!D5 -> D · training | F15: ='Training & Validation'!E5 -> 1 | G15: =IF(ISNUMBER(F15),INDEX('ERDR Iterations'!$K:$K,5+26*(F15-1)+10),"never processed (moved to D before its turn)") -> |L| > 1 → Step 5 corrects g
A16: S₂ | B16: ='Dataset'!B6 -> 10 | C16: ='Dataset'!P6 -> 2 | D16: =IF('Dataset'!B6=1,"S₁",IF('Dataset'!B6=10,"S₁₀",IF('Dataset'!B6<=10,"S"&'Dataset'!B6,"—"))) -> S₁₀ | E16: ='Training & Validation'!D6 -> D · training | F16: ='Training & Validation'!E6 -> 4 | G16: =IF(ISNUMBER(F16),INDEX('ERDR Iterations'!$K:$K,5+26*(F16-1)+10),"never processed (moved to D before its turn)") -> |L| = 1 → Sᵢ moves to D
A17: S₃ | B17: ='Dataset'!B7 -> 73 | C17: ='Dataset'!P7 -> 1 | D17: =IF('Dataset'!B7=1,"S₁",IF('Dataset'!B7=10,"S₁₀",IF('Dataset'!B7<=10,"S"&'Dataset'!B7,"—"))) -> — | E17: ='Training & Validation'!D7 -> F · validation | F17: ='Training & Validation'!E7 -> 2 | G17: =IF(ISNUMBER(F17),INDEX('ERDR Iterations'!$K:$K,5+26*(F17-1)+10),"never processed (moved to D before its turn)") -> |L| > 1 → Step 5 corrects g
A18: S₄ | B18: ='Dataset'!B8 -> 143 | C18: ='Dataset'!P8 -> 2 | D18: =IF('Dataset'!B8=1,"S₁",IF('Dataset'!B8=10,"S₁₀",IF('Dataset'!B8<=10,"S"&'Dataset'!B8,"—"))) -> — | E18: ='Training & Validation'!D8 -> F · validation | F18: ='Training & Validation'!E8 -> 6 | G18: =IF(ISNUMBER(F18),INDEX('ERDR Iterations'!$K:$K,5+26*(F18-1)+10),"never processed (moved to D before its turn)") -> |L| = 0 → Sᵢ is only blocked and stays in F
A19: S₅ | B19: ='Dataset'!B9 -> 224 | C19: ='Dataset'!P9 -> 2 | D19: =IF('Dataset'!B9=1,"S₁",IF('Dataset'!B9=10,"S₁₀",IF('Dataset'!B9<=10,"S"&'Dataset'!B9,"—"))) -> — | E19: ='Training & Validation'!D9 -> D · training | F19: ='Training & Validation'!E9 -> 3 | G19: =IF(ISNUMBER(F19),INDEX('ERDR Iterations'!$K:$K,5+26*(F19-1)+10),"never processed (moved to D before its turn)") -> |L| > 1 → Step 5 corrects g
A20: S₆ | B20: ='Dataset'!B10 -> 226 | C20: ='Dataset'!P10 -> 1 | D20: =IF('Dataset'!B10=1,"S₁",IF('Dataset'!B10=10,"S₁₀",IF('Dataset'!B10<=10,"S"&'Dataset'!B10,"—"))) -> — | E20: ='Training & Validation'!D10 -> D · training | F20: ='Training & Validation'!E10 -> 5 | G20: =IF(ISNUMBER(F20),INDEX('ERDR Iterations'!$K:$K,5+26*(F20-1)+10),"never processed (moved to D before its turn)") -> |L| = 1 → Sᵢ moves to D
A21: S₇ | B21: ='Dataset'!B11 -> 239 | C21: ='Dataset'!P11 -> 1 | D21: =IF('Dataset'!B11=1,"S₁",IF('Dataset'!B11=10,"S₁₀",IF('Dataset'!B11<=10,"S"&'Dataset'!B11,"—"))) -> — | E21: ='Training & Validation'!D11 -> D · training | F21: ='Training & Validation'!E11 -> — | G21: =IF(ISNUMBER(F21),INDEX('ERDR Iterations'!$K:$K,5+26*(F21-1)+10),"never processed (moved to D before its turn)") -> never processed (moved to D before its turn)
A23: Why this subset among the 403 seven-object samples
A24: • every one of the 17 cases occurs, and each of the 6 iterations shows a different case (|L| > 1 three times with different effects, |L| = 1 in both forms, |L| = 0);
A25: • each reading switch A, B, C changes the result on these objects, so the open points of the article are visible;
A26: • all ties are exact ties at d = 0 (z = r), the robust kind; the smallest gap between two different distances is 0.064, so there are no near-ties;
A27: • S₁ and S₂ are rows 1 and 10 — objects S₁ and S₁₀ of our earlier Heart-Disease (10, 13, 2) experiment.
A29: For comparison
A30: • A 6-object sample, rows 2, 8, 9, 54, 76, 219: shows the 14 branch cases and two moves in one Step 5, but no index tie and its validation set is the single object of row 54.
A31: • Taking the first rows of the file instead: rows 1–15 are needed for the 14 branch cases, rows 1–102 for all 17 cases.
A32: • N = 6 is not proven impossible for all 17 cases (the 3 + 3 search space has 1.5·10¹¹ subsets); the evidence above comes from a local search that aimed at exactly these cases.

Sheet Source Dataset (270)
A1: Source dataset · Heart-Disease (270, 13, 2) — the complete original sample (input; the experiment reads the selected rows from here)
A3: All 270 objects: 13 features x₁ … x₁₃, the class (1 / 2) and, in the last row, the feature types (1 = quantitative, 0 = nominal) · the 7 selected objects are highlighted
A4: Row | B4: x₁ | C4: x₂ | D4: x₃ | E4: x₄ | F4: x₅ | G4: x₆ | H4: x₇ | I4: x₈ | J4: x₉ | K4: x₁₀ | L4: x₁₁ | M4: x₁₂ | N4: x₁₃ | O4: Class | P4: Selected as
A5: 1 | B5: 70 | C5: 1 | D5: 4 | E5: 130 | F5: 322 | G5: 0 | H5: 2 | I5: 109 | J5: 0 | K5: 2.4 | L5: 2 | M5: 3 | N5: 3 | O5: 2 | P5: =IFERROR(CHOOSE(MATCH(A5,'Dataset'!$B$5:$B$11,0),"S₁","S₂","S₃","S₄","S₅","S₆","S₇"),"") -> S₁
A6: 2 | B6: 67 | C6: 0 | D6: 3 | E6: 115 | F6: 564 | G6: 0 | H6: 2 | I6: 160 | J6: 0 | K6: 1.6 | L6: 2 | M6: 0 | N6: 7 | O6: 1 | P6: =IFERROR(CHOOSE(MATCH(A6,'Dataset'!$B$5:$B$11,0),"S₁","S₂","S₃","S₄","S₅","S₆","S₇"),"")
A7: 3 | B7: 57 | C7: 1 | D7: 2 | E7: 124 | F7: 261 | G7: 0 | H7: 0 | I7: 141 | J7: 0 | K7: 0.3 | L7: 1 | M7: 0 | N7: 7 | O7: 2 | P7: =IFERROR(CHOOSE(MATCH(A7,'Dataset'!$B$5:$B$11,0),"S₁","S₂","S₃","S₄","S₅","S₆","S₇"),"")
A8: 4 | B8: 64 | C8: 1 | D8: 4 | E8: 128 | F8: 263 | G8: 0 | H8: 0 | I8: 105 | J8: 1 | K8: 0.2 | L8: 2 | M8: 1 | N8: 7 | O8: 1 | P8: =IFERROR(CHOOSE(MATCH(A8,'Dataset'!$B$5:$B$11,0),"S₁","S₂","S₃","S₄","S₅","S₆","S₇"),"")
A9: 5 | B9: 74 | C9: 0 | D9: 2 | E9: 120 | F9: 269 | G9: 0 | H9: 2 | I9: 121 | J9: 1 | K9: 0.2 | L9: 1 | M9: 1 | N9: 3 | O9: 1 | P9: =IFERROR(CHOOSE(MATCH(A9,'Dataset'!$B$5:$B$11,0),"S₁","S₂","S₃","S₄","S₅","S₆","S₇"),"")
A10: 6 | B10: 65 | C10: 1 | D10: 4 | E10: 120 | F10: 177 | G10: 0 | H10: 0 | I10: 140 | J10: 0 | K10: 0.4 | L10: 1 | M10: 0 | N10: 7 | O10: 1 | P10: =IFERROR(CHOOSE(MATCH(A10,'Dataset'!$B$5:$B$11,0),"S₁","S₂","S₃","S₄","S₅","S₆","S₇"),"")
A11: 7 | B11: 56 | C11: 1 | D11: 3 | E11: 130 | F11: 256 | G11: 1 | H11: 2 | I11: 142 | J11: 1 | K11: 0.6 | L11: 2 | M11: 1 | N11: 6 | O11: 2 | P11: =IFERROR(CHOOSE(MATCH(A11,'Dataset'!$B$5:$B$11,0),"S₁","S₂","S₃","S₄","S₅","S₆","S₇"),"")
A12: 8 | B12: 59 | C12: 1 | D12: 4 | E12: 110 | F12: 239 | G12: 0 | H12: 2 | I12: 142 | J12: 1 | K12: 1.2 | L12: 2 | M12: 1 | N12: 7 | O12: 2 | P12: =IFERROR(CHOOSE(MATCH(A12,'Dataset'!$B$5:$B$11,0),"S₁","S₂","S₃","S₄","S₅","S₆","S₇"),"")
A13: 9 | B13: 60 | C13: 1 | D13: 4 | E13: 140 | F13: 293 | G13: 0 | H13: 2 | I13: 170 | J13: 0 | K13: 1.2 | L13: 2 | M13: 2 | N13: 7 | O13: 2 | P13: =IFERROR(CHOOSE(MATCH(A13,'Dataset'!$B$5:$B$11,0),"S₁","S₂","S₃","S₄","S₅","S₆","S₇"),"")
A14: 10 | B14: 63 | C14: 0 | D14: 4 | E14: 150 | F14: 407 | G14: 0 | H14: 2 | I14: 154 | J14: 0 | K14: 4 | L14: 2 | M14: 3 | N14: 7 | O14: 2 | P14: =IFERROR(CHOOSE(MATCH(A14,'Dataset'!$B$5:$B$11,0),"S₁","S₂","S₃","S₄","S₅","S₆","S₇"),"") -> S₂
A15: 11 | B15: 59 | C15: 1 | D15: 4 | E15: 135 | F15: 234 | G15: 0 | H15: 0 | I15: 161 | J15: 0 | K15: 0.5 | L15: 2 | M15: 0 | N15: 7 | O15: 1 | P15: =IFERROR(CHOOSE(MATCH(A15,'Dataset'!$B$5:$B$11,0),"S₁","S₂","S₃","S₄","S₅","S₆","S₇"),"")
A16: 12 | B16: 53 | C16: 1 | D16: 4 | E16: 142 | F16: 226 | G16: 0 | H16: 2 | I16: 111 | J16: 1 | K16: 0 | L16: 1 | M16: 0 | N16: 7 | O16: 1 | P16: =IFERROR(CHOOSE(MATCH(A16,'Dataset'!$B$5:$B$11,0),"S₁","S₂","S₃","S₄","S₅","S₆","S₇"),"")
... A274: 270 | B274: 67 | C274: 1 | D274: 4 | E274: 160 | F274: 286 | G274: 0 | H274: 2 | I274: 108 | J274: 1 | K274: 1.5 | L274: 2 | M274: 3 | N274: 3 | O274: 2 | P274: =IFERROR(CHOOSE(MATCH(A274,'Dataset'!$B$5:$B$11,0),"S₁","S₂","S₃","S₄","S₅","S₆","S₇"),"")
A275: Type | B275: 1 | C275: 0 | D275: 0 | E275: 1 | F275: 1 | G275: 0 | H275: 0 | I275: 1 | J275: 0 | K275: 1 | L275: 0 | M275: 1 | N275: 0 | O275: 1 = I
A277: Class 1 | B277: =COUNTIF(O5:O274,1) -> 150
A278: Class 2 | B278: =COUNTIF(O5:O274,2) -> 120
A279: Objects | B279: =COUNT(O5:O274) -> 270
A281: Source: the lab file Heart-Disease (270,13,2).csv — first line "270,13,2" (objects, features, classes), 270 object lines, last line = type flags (the Statlog Heart data).
A282: Type flags as in the file: x₁, x₄, x₅, x₈, x₁₀, x₁₂ quantitative (6); x₂, x₃, x₆, x₇, x₉, x₁₁, x₁₃ nominal (7) — the same as in Heart-Disease (10, 13, 2), whose 10 objects are rows 1–10 here.
A283: The article (§3) counts 7 quantitative and 6 nominal features (probably x₁₁, the ordered slope, as quantitative); this workbook keeps the file’s flags.

Sheet Dataset
A1: Dataset · Heart-Disease (7, 13, 2) — the 7 objects selected from Heart-Disease (270, 13, 2) for the ERDR experiment
A3: Selected objects S₁ … S₇ (source rows in ascending order) · values are read from “Source Dataset (270)” — type another source row to try another object
A4: № | B4: Source row | C4: x₁ | D4: x₂ | E4: x₃ | F4: x₄ | G4: x₅ | H4: x₆ | I4: x₇ | J4: x₈ | K4: x₉ | L4: x₁₀ | M4: x₁₁ | N4: x₁₂ | O4: x₁₃ | P4: Class
A5: S₁ | B5: 1 | C5: =INDEX('Source Dataset (270)'!B$5:B$274,$B5) -> 70 | D5: =INDEX('Source Dataset (270)'!C$5:C$274,$B5) -> 1 | E5: =INDEX('Source Dataset (270)'!D$5:D$274,$B5) -> 4 | F5: =INDEX('Source Dataset (270)'!E$5:E$274,$B5) -> 130 | G5: =INDEX('Source Dataset (270)'!F$5:F$274,$B5) -> 322 | H5: =INDEX('Source Dataset (270)'!G$5:G$274,$B5) -> 0 | I5: =INDEX('Source Dataset (270)'!H$5:H$274,$B5) -> 2 | J5: =INDEX('Source Dataset (270)'!I$5:I$274,$B5) -> 109 | ... O5: =INDEX('Source Dataset (270)'!N$5:N$274,$B5) -> 3 | P5: =INDEX('Source Dataset (270)'!$O$5:$O$274,$B5) -> 2
A6: S₂ | B6: 10 | C6: =INDEX('Source Dataset (270)'!B$5:B$274,$B6) -> 63 | D6: =INDEX('Source Dataset (270)'!C$5:C$274,$B6) -> 0 | E6: =INDEX('Source Dataset (270)'!D$5:D$274,$B6) -> 4 | F6: =INDEX('Source Dataset (270)'!E$5:E$274,$B6) -> 150 | G6: =INDEX('Source Dataset (270)'!F$5:F$274,$B6) -> 407 | H6: =INDEX('Source Dataset (270)'!G$5:G$274,$B6) -> 0 | I6: =INDEX('Source Dataset (270)'!H$5:H$274,$B6) -> 2 | J6: =INDEX('Source Dataset (270)'!I$5:I$274,$B6) -> 154 | ... O6: =INDEX('Source Dataset (270)'!N$5:N$274,$B6) -> 7 | P6: =INDEX('Source Dataset (270)'!$O$5:$O$274,$B6) -> 2
A7: S₃ | B7: 73 | C7: =INDEX('Source Dataset (270)'!B$5:B$274,$B7) -> 70 | D7: =INDEX('Source Dataset (270)'!C$5:C$274,$B7) -> 1 | E7: =INDEX('Source Dataset (270)'!D$5:D$274,$B7) -> 2 | F7: =INDEX('Source Dataset (270)'!E$5:E$274,$B7) -> 156 | G7: =INDEX('Source Dataset (270)'!F$5:F$274,$B7) -> 245 | H7: =INDEX('Source Dataset (270)'!G$5:G$274,$B7) -> 0 | I7: =INDEX('Source Dataset (270)'!H$5:H$274,$B7) -> 2 | J7: =INDEX('Source Dataset (270)'!I$5:I$274,$B7) -> 143 | ... O7: =INDEX('Source Dataset (270)'!N$5:N$274,$B7) -> 3 | P7: =INDEX('Source Dataset (270)'!$O$5:$O$274,$B7) -> 1
A8: S₄ | B8: 143 | C8: =INDEX('Source Dataset (270)'!B$5:B$274,$B8) -> 50 | D8: =INDEX('Source Dataset (270)'!C$5:C$274,$B8) -> 1 | E8: =INDEX('Source Dataset (270)'!D$5:D$274,$B8) -> 3 | F8: =INDEX('Source Dataset (270)'!E$5:E$274,$B8) -> 140 | G8: =INDEX('Source Dataset (270)'!F$5:F$274,$B8) -> 233 | H8: =INDEX('Source Dataset (270)'!G$5:G$274,$B8) -> 0 | I8: =INDEX('Source Dataset (270)'!H$5:H$274,$B8) -> 0 | J8: =INDEX('Source Dataset (270)'!I$5:I$274,$B8) -> 163 | ... O8: =INDEX('Source Dataset (270)'!N$5:N$274,$B8) -> 7 | P8: =INDEX('Source Dataset (270)'!$O$5:$O$274,$B8) -> 2
A9: S₅ | B9: 224 | C9: =INDEX('Source Dataset (270)'!B$5:B$274,$B9) -> 63 | D9: =INDEX('Source Dataset (270)'!C$5:C$274,$B9) -> 1 | E9: =INDEX('Source Dataset (270)'!D$5:D$274,$B9) -> 4 | F9: =INDEX('Source Dataset (270)'!E$5:E$274,$B9) -> 130 | G9: =INDEX('Source Dataset (270)'!F$5:F$274,$B9) -> 330 | H9: =INDEX('Source Dataset (270)'!G$5:G$274,$B9) -> 1 | I9: =INDEX('Source Dataset (270)'!H$5:H$274,$B9) -> 2 | J9: =INDEX('Source Dataset (270)'!I$5:I$274,$B9) -> 132 | ... O9: =INDEX('Source Dataset (270)'!N$5:N$274,$B9) -> 7 | P9: =INDEX('Source Dataset (270)'!$O$5:$O$274,$B9) -> 2
A10: S₆ | B10: 226 | C10: =INDEX('Source Dataset (270)'!B$5:B$274,$B10) -> 41 | D10: =INDEX('Source Dataset (270)'!C$5:C$274,$B10) -> 1 | E10: =INDEX('Source Dataset (270)'!D$5:D$274,$B10) -> 2 | F10: =INDEX('Source Dataset (270)'!E$5:E$274,$B10) -> 135 | G10: =INDEX('Source Dataset (270)'!F$5:F$274,$B10) -> 203 | H10: =INDEX('Source Dataset (270)'!G$5:G$274,$B10) -> 0 | I10: =INDEX('Source Dataset (270)'!H$5:H$274,$B10) -> 0 | J10: =INDEX('Source Dataset (270)'!I$5:I$274,$B10) -> 132 | ... O10: =INDEX('Source Dataset (270)'!N$5:N$274,$B10) -> 6 | P10: =INDEX('Source Dataset (270)'!$O$5:$O$274,$B10) -> 1
A11: S₇ | B11: 239 | C11: =INDEX('Source Dataset (270)'!B$5:B$274,$B11) -> 47 | D11: =INDEX('Source Dataset (270)'!C$5:C$274,$B11) -> 1 | E11: =INDEX('Source Dataset (270)'!D$5:D$274,$B11) -> 3 | F11: =INDEX('Source Dataset (270)'!E$5:E$274,$B11) -> 138 | G11: =INDEX('Source Dataset (270)'!F$5:F$274,$B11) -> 257 | H11: =INDEX('Source Dataset (270)'!G$5:G$274,$B11) -> 0 | I11: =INDEX('Source Dataset (270)'!H$5:H$274,$B11) -> 2 | J11: =INDEX('Source Dataset (270)'!I$5:I$274,$B11) -> 156 | ... O11: =INDEX('Source Dataset (270)'!N$5:N$274,$B11) -> 3 | P11: =INDEX('Source Dataset (270)'!$O$5:$O$274,$B11) -> 1
A12: Type | B12: — | C12: ='Source Dataset (270)'!B$275 -> 1 | D12: ='Source Dataset (270)'!C$275 -> 0 | E12: ='Source Dataset (270)'!D$275 -> 0 | F12: ='Source Dataset (270)'!E$275 -> 1 | G12: ='Source Dataset (270)'!F$275 -> 1 | H12: ='Source Dataset (270)'!G$275 -> 0 | I12: ='Source Dataset (270)'!H$275 -> 0 | J12: ='Source Dataset (270)'!I$275 -> 1 | ... O12: ='Source Dataset (270)'!N$275 -> 0 | P12: 1 = I
A14: Check | B14: =IF(AND(B5<B6,B6<B7,B7<B8,B8<B9,B9<B10,B10<B11,B5>=1,B11<=270),"✓ 7 distinct source rows in ascending order","⚠ the source rows must be distinct, ascending and between 1 and 270") -> ✓ 7 distinct source rows in ascending order
A16: Quantitative features (set I, type 1) with class — view of the table above
A17: № | B17: Source row | C17: x₁ | D17: x₄ | E17: x₅ | F17: x₈ | G17: x₁₀ | H17: x₁₂ | I17: Class
A18: S₁ | B18: =B5 -> 1 | C18: =C5 -> 70 | D18: =F5 -> 130 | E18: =G5 -> 322 | F18: =J5 -> 109 | G18: =L5 -> 2.4 | H18: =N5 -> 3 | I18: =P5 -> 2
A19: S₂ | B19: =B6 -> 10 | C19: =C6 -> 63 | D19: =F6 -> 150 | E19: =G6 -> 407 | F19: =J6 -> 154 | G19: =L6 -> 4 | H19: =N6 -> 3 | I19: =P6 -> 2
A20: S₃ | B20: =B7 -> 73 | C20: =C7 -> 70 | D20: =F7 -> 156 | E20: =G7 -> 245 | F20: =J7 -> 143 | G20: =L7 -> 0 | H20: =N7 -> 0 | I20: =P7 -> 1
A21: S₄ | B21: =B8 -> 143 | C21: =C8 -> 50 | D21: =F8 -> 140 | E21: =G8 -> 233 | F21: =J8 -> 163 | G21: =L8 -> 0.6 | H21: =N8 -> 1 | I21: =P8 -> 2
A22: S₅ | B22: =B9 -> 224 | C22: =C9 -> 63 | D22: =F9 -> 130 | E22: =G9 -> 330 | F22: =J9 -> 132 | G22: =L9 -> 1.8 | H22: =N9 -> 3 | I22: =P9 -> 2
A23: S₆ | B23: =B10 -> 226 | C23: =C10 -> 41 | D23: =F10 -> 135 | E23: =G10 -> 203 | F23: =J10 -> 132 | G23: =L10 -> 0 | H23: =N10 -> 0 | I23: =P10 -> 1
A24: S₇ | B24: =B11 -> 239 | C24: =C11 -> 47 | D24: =F11 -> 138 | E24: =G11 -> 257 | F24: =J11 -> 156 | G24: =L11 -> 0 | H24: =N11 -> 0 | I24: =P11 -> 1
A27: Nominal features (set J, type 0) with class — view of the table above
A28: № | B28: Source row | C28: x₂ | D28: x₃ | E28: x₆ | F28: x₇ | G28: x₉ | H28: x₁₁ | I28: x₁₃ | J28: Class
A29: S₁ | B29: =B5 -> 1 | C29: =D5 -> 1 | D29: =E5 -> 4 | E29: =H5 -> 0 | F29: =I5 -> 2 | G29: =K5 -> 0 | H29: =M5 -> 2 | I29: =O5 -> 3 | J29: =P5 -> 2
A30: S₂ | B30: =B6 -> 10 | C30: =D6 -> 0 | D30: =E6 -> 4 | E30: =H6 -> 0 | F30: =I6 -> 2 | G30: =K6 -> 0 | H30: =M6 -> 2 | I30: =O6 -> 7 | J30: =P6 -> 2
A31: S₃ | B31: =B7 -> 73 | C31: =D7 -> 1 | D31: =E7 -> 2 | E31: =H7 -> 0 | F31: =I7 -> 2 | G31: =K7 -> 0 | H31: =M7 -> 1 | I31: =O7 -> 3 | J31: =P7 -> 1
A32: S₄ | B32: =B8 -> 143 | C32: =D8 -> 1 | D32: =E8 -> 3 | E32: =H8 -> 0 | F32: =I8 -> 0 | G32: =K8 -> 0 | H32: =M8 -> 2 | I32: =O8 -> 7 | J32: =P8 -> 2
A33: S₅ | B33: =B9 -> 224 | C33: =D9 -> 1 | D33: =E9 -> 4 | E33: =H9 -> 1 | F33: =I9 -> 2 | G33: =K9 -> 1 | H33: =M9 -> 1 | I33: =O9 -> 7 | J33: =P9 -> 2
A34: S₆ | B34: =B10 -> 226 | C34: =D10 -> 1 | D34: =E10 -> 2 | E34: =H10 -> 0 | F34: =I10 -> 0 | G34: =K10 -> 0 | H34: =M10 -> 2 | I34: =O10 -> 6 | J34: =P10 -> 1
A35: S₇ | B35: =B11 -> 239 | C35: =D11 -> 1 | D35: =E11 -> 3 | E35: =H11 -> 0 | F35: =I11 -> 2 | G35: =K11 -> 0 | H35: =M11 -> 1 | I35: =O11 -> 3 | J35: =P11 -> 1
A38: Source rows 1 and 10 are S₁ and S₁₀ of the earlier Heart-Disease (10, 13, 2) experiment; here they are S₁ and S₂.
A39: The two lower tables split the features by the type flags of the source file (6 quantitative, 7 nominal); every calculation uses the Type row above.
A40: Why exactly these 7 objects: the smallest sample in which every case of the ERDR algorithm occurs — see “Object Selection” and “Case Checklist”.

Sheet Normalized Dataset
A1: Step 0 · Scale unification — quantitative features mapped to [0, 1], nominal features unchanged (required by the Zhuravlev metric)
A3: Heart-Disease (7, 13, 2) after x′ = (x − min) / (max − min) for type 1 (min and max over the 7 objects)
A4: № | B4: x₁ | C4: x₂ | D4: x₃ | E4: x₄ | F4: x₅ | G4: x₆ | H4: x₇ | I4: x₈ | J4: x₉ | K4: x₁₀ | L4: x₁₁ | M4: x₁₂ | N4: x₁₃ | O4: Class
A5: S₁ | B5: =IF('Dataset'!C$12=1,IF(MAX('Dataset'!C$5:C$11)=MIN('Dataset'!C$5:C$11),0,('Dataset'!C5-MIN('Dataset'!C$5:C$11))/(MAX('Dataset'!C$5:C$11)-MIN('Dataset'!C$5:C$11))),'Dataset'!C5) -> 1 | C5: =IF('Dataset'!D$12=1,IF(MAX('Dataset'!D$5:D$11)=MIN('Dataset'!D$5:D$11),0,('Dataset'!D5-MIN('Dataset'!D$5:D$11))/(MAX('Dataset'!D$5:D$11)-MIN('Dataset'!D$5:D$11))),'Dataset'!D5) -> 1 | D5: =IF('Dataset'!E$12=1,IF(MAX('Dataset'!E$5:E$11)=MIN('Dataset'!E$5:E$11),0,('Dataset'!E5-MIN('Dataset'!E$5:E$11))/(MAX('Dataset'!E$5:E$11)-MIN('Dataset'!E$5:E$11))),'Dataset'!E5) -> 4 | E5: =IF('Dataset'!F$12=1,IF(MAX('Dataset'!F$5:F$11)=MIN('Dataset'!F$5:F$11),0,('Dataset'!F5-MIN('Dataset'!F$5:F$11))/(MAX('Dataset'!F$5:F$11)-MIN('Dataset'!F$5:F$11))),'Dataset'!F5) -> 0 | F5: =IF('Dataset'!G$12=1,IF(MAX('Dataset'!G$5:G$11)=MIN('Dataset'!G$5:G$11),0,('Dataset'!G5-MIN('Dataset'!G$5:G$11))/(MAX('Dataset'!G$5:G$11)-MIN('Dataset'!G$5:G$11))),'Dataset'!G5) -> 0.58333333 | G5: =IF('Dataset'!H$12=1,IF(MAX('Dataset'!H$5:H$11)=MIN('Dataset'!H$5:H$11),0,('Dataset'!H5-MIN('Dataset'!H$5:H$11))/(MAX('Dataset'!H$5:H$11)-MIN('Dataset'!H$5:H$11))),'Dataset'!H5) -> 0 | H5: =IF('Dataset'!I$12=1,IF(MAX('Dataset'!I$5:I$11)=MIN('Dataset'!I$5:I$11),0,('Dataset'!I5-MIN('Dataset'!I$5:I$11))/(MAX('Dataset'!I$5:I$11)-MIN('Dataset'!I$5:I$11))),'Dataset'!I5) -> 2 | I5: =IF('Dataset'!J$12=1,IF(MAX('Dataset'!J$5:J$11)=MIN('Dataset'!J$5:J$11),0,('Dataset'!J5-MIN('Dataset'!J$5:J$11))/(MAX('Dataset'!J$5:J$11)-MIN('Dataset'!J$5:J$11))),'Dataset'!J5) -> 0 | ... N5: =IF('Dataset'!O$12=1,IF(MAX('Dataset'!O$5:O$11)=MIN('Dataset'!O$5:O$11),0,('Dataset'!O5-MIN('Dataset'!O$5:O$11))/(MAX('Dataset'!O$5:O$11)-MIN('Dataset'!O$5:O$11))),'Dataset'!O5) -> 3 | O5: ='Dataset'!P5 -> 2
A6: S₂ | B6: =IF('Dataset'!C$12=1,IF(MAX('Dataset'!C$5:C$11)=MIN('Dataset'!C$5:C$11),0,('Dataset'!C6-MIN('Dataset'!C$5:C$11))/(MAX('Dataset'!C$5:C$11)-MIN('Dataset'!C$5:C$11))),'Dataset'!C6) -> 0.75862069 | C6: =IF('Dataset'!D$12=1,IF(MAX('Dataset'!D$5:D$11)=MIN('Dataset'!D$5:D$11),0,('Dataset'!D6-MIN('Dataset'!D$5:D$11))/(MAX('Dataset'!D$5:D$11)-MIN('Dataset'!D$5:D$11))),'Dataset'!D6) -> 0 | D6: =IF('Dataset'!E$12=1,IF(MAX('Dataset'!E$5:E$11)=MIN('Dataset'!E$5:E$11),0,('Dataset'!E6-MIN('Dataset'!E$5:E$11))/(MAX('Dataset'!E$5:E$11)-MIN('Dataset'!E$5:E$11))),'Dataset'!E6) -> 4 | E6: =IF('Dataset'!F$12=1,IF(MAX('Dataset'!F$5:F$11)=MIN('Dataset'!F$5:F$11),0,('Dataset'!F6-MIN('Dataset'!F$5:F$11))/(MAX('Dataset'!F$5:F$11)-MIN('Dataset'!F$5:F$11))),'Dataset'!F6) -> 0.76923077 | F6: =IF('Dataset'!G$12=1,IF(MAX('Dataset'!G$5:G$11)=MIN('Dataset'!G$5:G$11),0,('Dataset'!G6-MIN('Dataset'!G$5:G$11))/(MAX('Dataset'!G$5:G$11)-MIN('Dataset'!G$5:G$11))),'Dataset'!G6) -> 1 | G6: =IF('Dataset'!H$12=1,IF(MAX('Dataset'!H$5:H$11)=MIN('Dataset'!H$5:H$11),0,('Dataset'!H6-MIN('Dataset'!H$5:H$11))/(MAX('Dataset'!H$5:H$11)-MIN('Dataset'!H$5:H$11))),'Dataset'!H6) -> 0 | H6: =IF('Dataset'!I$12=1,IF(MAX('Dataset'!I$5:I$11)=MIN('Dataset'!I$5:I$11),0,('Dataset'!I6-MIN('Dataset'!I$5:I$11))/(MAX('Dataset'!I$5:I$11)-MIN('Dataset'!I$5:I$11))),'Dataset'!I6) -> 2 | I6: =IF('Dataset'!J$12=1,IF(MAX('Dataset'!J$5:J$11)=MIN('Dataset'!J$5:J$11),0,('Dataset'!J6-MIN('Dataset'!J$5:J$11))/(MAX('Dataset'!J$5:J$11)-MIN('Dataset'!J$5:J$11))),'Dataset'!J6) -> 0.83333333 | ... N6: =IF('Dataset'!O$12=1,IF(MAX('Dataset'!O$5:O$11)=MIN('Dataset'!O$5:O$11),0,('Dataset'!O6-MIN('Dataset'!O$5:O$11))/(MAX('Dataset'!O$5:O$11)-MIN('Dataset'!O$5:O$11))),'Dataset'!O6) -> 7 | O6: ='Dataset'!P6 -> 2
A7: S₃ | B7: =IF('Dataset'!C$12=1,IF(MAX('Dataset'!C$5:C$11)=MIN('Dataset'!C$5:C$11),0,('Dataset'!C7-MIN('Dataset'!C$5:C$11))/(MAX('Dataset'!C$5:C$11)-MIN('Dataset'!C$5:C$11))),'Dataset'!C7) -> 1 | C7: =IF('Dataset'!D$12=1,IF(MAX('Dataset'!D$5:D$11)=MIN('Dataset'!D$5:D$11),0,('Dataset'!D7-MIN('Dataset'!D$5:D$11))/(MAX('Dataset'!D$5:D$11)-MIN('Dataset'!D$5:D$11))),'Dataset'!D7) -> 1 | D7: =IF('Dataset'!E$12=1,IF(MAX('Dataset'!E$5:E$11)=MIN('Dataset'!E$5:E$11),0,('Dataset'!E7-MIN('Dataset'!E$5:E$11))/(MAX('Dataset'!E$5:E$11)-MIN('Dataset'!E$5:E$11))),'Dataset'!E7) -> 2 | E7: =IF('Dataset'!F$12=1,IF(MAX('Dataset'!F$5:F$11)=MIN('Dataset'!F$5:F$11),0,('Dataset'!F7-MIN('Dataset'!F$5:F$11))/(MAX('Dataset'!F$5:F$11)-MIN('Dataset'!F$5:F$11))),'Dataset'!F7) -> 1 | F7: =IF('Dataset'!G$12=1,IF(MAX('Dataset'!G$5:G$11)=MIN('Dataset'!G$5:G$11),0,('Dataset'!G7-MIN('Dataset'!G$5:G$11))/(MAX('Dataset'!G$5:G$11)-MIN('Dataset'!G$5:G$11))),'Dataset'!G7) -> 0.20588235 | G7: =IF('Dataset'!H$12=1,IF(MAX('Dataset'!H$5:H$11)=MIN('Dataset'!H$5:H$11),0,('Dataset'!H7-MIN('Dataset'!H$5:H$11))/(MAX('Dataset'!H$5:H$11)-MIN('Dataset'!H$5:H$11))),'Dataset'!H7) -> 0 | H7: =IF('Dataset'!I$12=1,IF(MAX('Dataset'!I$5:I$11)=MIN('Dataset'!I$5:I$11),0,('Dataset'!I7-MIN('Dataset'!I$5:I$11))/(MAX('Dataset'!I$5:I$11)-MIN('Dataset'!I$5:I$11))),'Dataset'!I7) -> 2 | I7: =IF('Dataset'!J$12=1,IF(MAX('Dataset'!J$5:J$11)=MIN('Dataset'!J$5:J$11),0,('Dataset'!J7-MIN('Dataset'!J$5:J$11))/(MAX('Dataset'!J$5:J$11)-MIN('Dataset'!J$5:J$11))),'Dataset'!J7) -> 0.62962963 | ... N7: =IF('Dataset'!O$12=1,IF(MAX('Dataset'!O$5:O$11)=MIN('Dataset'!O$5:O$11),0,('Dataset'!O7-MIN('Dataset'!O$5:O$11))/(MAX('Dataset'!O$5:O$11)-MIN('Dataset'!O$5:O$11))),'Dataset'!O7) -> 3 | O7: ='Dataset'!P7 -> 1
A8: S₄ | B8: =IF('Dataset'!C$12=1,IF(MAX('Dataset'!C$5:C$11)=MIN('Dataset'!C$5:C$11),0,('Dataset'!C8-MIN('Dataset'!C$5:C$11))/(MAX('Dataset'!C$5:C$11)-MIN('Dataset'!C$5:C$11))),'Dataset'!C8) -> 0.31034483 | C8: =IF('Dataset'!D$12=1,IF(MAX('Dataset'!D$5:D$11)=MIN('Dataset'!D$5:D$11),0,('Dataset'!D8-MIN('Dataset'!D$5:D$11))/(MAX('Dataset'!D$5:D$11)-MIN('Dataset'!D$5:D$11))),'Dataset'!D8) -> 1 | D8: =IF('Dataset'!E$12=1,IF(MAX('Dataset'!E$5:E$11)=MIN('Dataset'!E$5:E$11),0,('Dataset'!E8-MIN('Dataset'!E$5:E$11))/(MAX('Dataset'!E$5:E$11)-MIN('Dataset'!E$5:E$11))),'Dataset'!E8) -> 3 | E8: =IF('Dataset'!F$12=1,IF(MAX('Dataset'!F$5:F$11)=MIN('Dataset'!F$5:F$11),0,('Dataset'!F8-MIN('Dataset'!F$5:F$11))/(MAX('Dataset'!F$5:F$11)-MIN('Dataset'!F$5:F$11))),'Dataset'!F8) -> 0.38461538 | F8: =IF('Dataset'!G$12=1,IF(MAX('Dataset'!G$5:G$11)=MIN('Dataset'!G$5:G$11),0,('Dataset'!G8-MIN('Dataset'!G$5:G$11))/(MAX('Dataset'!G$5:G$11)-MIN('Dataset'!G$5:G$11))),'Dataset'!G8) -> 0.14705882 | G8: =IF('Dataset'!H$12=1,IF(MAX('Dataset'!H$5:H$11)=MIN('Dataset'!H$5:H$11),0,('Dataset'!H8-MIN('Dataset'!H$5:H$11))/(MAX('Dataset'!H$5:H$11)-MIN('Dataset'!H$5:H$11))),'Dataset'!H8) -> 0 | H8: =IF('Dataset'!I$12=1,IF(MAX('Dataset'!I$5:I$11)=MIN('Dataset'!I$5:I$11),0,('Dataset'!I8-MIN('Dataset'!I$5:I$11))/(MAX('Dataset'!I$5:I$11)-MIN('Dataset'!I$5:I$11))),'Dataset'!I8) -> 0 | I8: =IF('Dataset'!J$12=1,IF(MAX('Dataset'!J$5:J$11)=MIN('Dataset'!J$5:J$11),0,('Dataset'!J8-MIN('Dataset'!J$5:J$11))/(MAX('Dataset'!J$5:J$11)-MIN('Dataset'!J$5:J$11))),'Dataset'!J8) -> 1 | ... N8: =IF('Dataset'!O$12=1,IF(MAX('Dataset'!O$5:O$11)=MIN('Dataset'!O$5:O$11),0,('Dataset'!O8-MIN('Dataset'!O$5:O$11))/(MAX('Dataset'!O$5:O$11)-MIN('Dataset'!O$5:O$11))),'Dataset'!O8) -> 7 | O8: ='Dataset'!P8 -> 2
A9: S₅ | B9: =IF('Dataset'!C$12=1,IF(MAX('Dataset'!C$5:C$11)=MIN('Dataset'!C$5:C$11),0,('Dataset'!C9-MIN('Dataset'!C$5:C$11))/(MAX('Dataset'!C$5:C$11)-MIN('Dataset'!C$5:C$11))),'Dataset'!C9) -> 0.75862069 | C9: =IF('Dataset'!D$12=1,IF(MAX('Dataset'!D$5:D$11)=MIN('Dataset'!D$5:D$11),0,('Dataset'!D9-MIN('Dataset'!D$5:D$11))/(MAX('Dataset'!D$5:D$11)-MIN('Dataset'!D$5:D$11))),'Dataset'!D9) -> 1 | D9: =IF('Dataset'!E$12=1,IF(MAX('Dataset'!E$5:E$11)=MIN('Dataset'!E$5:E$11),0,('Dataset'!E9-MIN('Dataset'!E$5:E$11))/(MAX('Dataset'!E$5:E$11)-MIN('Dataset'!E$5:E$11))),'Dataset'!E9) -> 4 | E9: =IF('Dataset'!F$12=1,IF(MAX('Dataset'!F$5:F$11)=MIN('Dataset'!F$5:F$11),0,('Dataset'!F9-MIN('Dataset'!F$5:F$11))/(MAX('Dataset'!F$5:F$11)-MIN('Dataset'!F$5:F$11))),'Dataset'!F9) -> 0 | F9: =IF('Dataset'!G$12=1,IF(MAX('Dataset'!G$5:G$11)=MIN('Dataset'!G$5:G$11),0,('Dataset'!G9-MIN('Dataset'!G$5:G$11))/(MAX('Dataset'!G$5:G$11)-MIN('Dataset'!G$5:G$11))),'Dataset'!G9) -> 0.62254902 | G9: =IF('Dataset'!H$12=1,IF(MAX('Dataset'!H$5:H$11)=MIN('Dataset'!H$5:H$11),0,('Dataset'!H9-MIN('Dataset'!H$5:H$11))/(MAX('Dataset'!H$5:H$11)-MIN('Dataset'!H$5:H$11))),'Dataset'!H9) -> 1 | H9: =IF('Dataset'!I$12=1,IF(MAX('Dataset'!I$5:I$11)=MIN('Dataset'!I$5:I$11),0,('Dataset'!I9-MIN('Dataset'!I$5:I$11))/(MAX('Dataset'!I$5:I$11)-MIN('Dataset'!I$5:I$11))),'Dataset'!I9) -> 2 | I9: =IF('Dataset'!J$12=1,IF(MAX('Dataset'!J$5:J$11)=MIN('Dataset'!J$5:J$11),0,('Dataset'!J9-MIN('Dataset'!J$5:J$11))/(MAX('Dataset'!J$5:J$11)-MIN('Dataset'!J$5:J$11))),'Dataset'!J9) -> 0.42592593 | ... N9: =IF('Dataset'!O$12=1,IF(MAX('Dataset'!O$5:O$11)=MIN('Dataset'!O$5:O$11),0,('Dataset'!O9-MIN('Dataset'!O$5:O$11))/(MAX('Dataset'!O$5:O$11)-MIN('Dataset'!O$5:O$11))),'Dataset'!O9) -> 7 | O9: ='Dataset'!P9 -> 2
A10: S₆ | B10: =IF('Dataset'!C$12=1,IF(MAX('Dataset'!C$5:C$11)=MIN('Dataset'!C$5:C$11),0,('Dataset'!C10-MIN('Dataset'!C$5:C$11))/(MAX('Dataset'!C$5:C$11)-MIN('Dataset'!C$5:C$11))),'Dataset'!C10) -> 0 | C10: =IF('Dataset'!D$12=1,IF(MAX('Dataset'!D$5:D$11)=MIN('Dataset'!D$5:D$11),0,('Dataset'!D10-MIN('Dataset'!D$5:D$11))/(MAX('Dataset'!D$5:D$11)-MIN('Dataset'!D$5:D$11))),'Dataset'!D10) -> 1 | D10: =IF('Dataset'!E$12=1,IF(MAX('Dataset'!E$5:E$11)=MIN('Dataset'!E$5:E$11),0,('Dataset'!E10-MIN('Dataset'!E$5:E$11))/(MAX('Dataset'!E$5:E$11)-MIN('Dataset'!E$5:E$11))),'Dataset'!E10) -> 2 | E10: =IF('Dataset'!F$12=1,IF(MAX('Dataset'!F$5:F$11)=MIN('Dataset'!F$5:F$11),0,('Dataset'!F10-MIN('Dataset'!F$5:F$11))/(MAX('Dataset'!F$5:F$11)-MIN('Dataset'!F$5:F$11))),'Dataset'!F10) -> 0.19230769 | F10: =IF('Dataset'!G$12=1,IF(MAX('Dataset'!G$5:G$11)=MIN('Dataset'!G$5:G$11),0,('Dataset'!G10-MIN('Dataset'!G$5:G$11))/(MAX('Dataset'!G$5:G$11)-MIN('Dataset'!G$5:G$11))),'Dataset'!G10) -> 0 | G10: =IF('Dataset'!H$12=1,IF(MAX('Dataset'!H$5:H$11)=MIN('Dataset'!H$5:H$11),0,('Dataset'!H10-MIN('Dataset'!H$5:H$11))/(MAX('Dataset'!H$5:H$11)-MIN('Dataset'!H$5:H$11))),'Dataset'!H10) -> 0 | H10: =IF('Dataset'!I$12=1,IF(MAX('Dataset'!I$5:I$11)=MIN('Dataset'!I$5:I$11),0,('Dataset'!I10-MIN('Dataset'!I$5:I$11))/(MAX('Dataset'!I$5:I$11)-MIN('Dataset'!I$5:I$11))),'Dataset'!I10) -> 0 | I10: =IF('Dataset'!J$12=1,IF(MAX('Dataset'!J$5:J$11)=MIN('Dataset'!J$5:J$11),0,('Dataset'!J10-MIN('Dataset'!J$5:J$11))/(MAX('Dataset'!J$5:J$11)-MIN('Dataset'!J$5:J$11))),'Dataset'!J10) -> 0.42592593 | ... N10: =IF('Dataset'!O$12=1,IF(MAX('Dataset'!O$5:O$11)=MIN('Dataset'!O$5:O$11),0,('Dataset'!O10-MIN('Dataset'!O$5:O$11))/(MAX('Dataset'!O$5:O$11)-MIN('Dataset'!O$5:O$11))),'Dataset'!O10) -> 6 | O10: ='Dataset'!P10 -> 1
A11: S₇ | B11: =IF('Dataset'!C$12=1,IF(MAX('Dataset'!C$5:C$11)=MIN('Dataset'!C$5:C$11),0,('Dataset'!C11-MIN('Dataset'!C$5:C$11))/(MAX('Dataset'!C$5:C$11)-MIN('Dataset'!C$5:C$11))),'Dataset'!C11) -> 0.20689655 | C11: =IF('Dataset'!D$12=1,IF(MAX('Dataset'!D$5:D$11)=MIN('Dataset'!D$5:D$11),0,('Dataset'!D11-MIN('Dataset'!D$5:D$11))/(MAX('Dataset'!D$5:D$11)-MIN('Dataset'!D$5:D$11))),'Dataset'!D11) -> 1 | D11: =IF('Dataset'!E$12=1,IF(MAX('Dataset'!E$5:E$11)=MIN('Dataset'!E$5:E$11),0,('Dataset'!E11-MIN('Dataset'!E$5:E$11))/(MAX('Dataset'!E$5:E$11)-MIN('Dataset'!E$5:E$11))),'Dataset'!E11) -> 3 | E11: =IF('Dataset'!F$12=1,IF(MAX('Dataset'!F$5:F$11)=MIN('Dataset'!F$5:F$11),0,('Dataset'!F11-MIN('Dataset'!F$5:F$11))/(MAX('Dataset'!F$5:F$11)-MIN('Dataset'!F$5:F$11))),'Dataset'!F11) -> 0.30769231 | F11: =IF('Dataset'!G$12=1,IF(MAX('Dataset'!G$5:G$11)=MIN('Dataset'!G$5:G$11),0,('Dataset'!G11-MIN('Dataset'!G$5:G$11))/(MAX('Dataset'!G$5:G$11)-MIN('Dataset'!G$5:G$11))),'Dataset'!G11) -> 0.26470588 | G11: =IF('Dataset'!H$12=1,IF(MAX('Dataset'!H$5:H$11)=MIN('Dataset'!H$5:H$11),0,('Dataset'!H11-MIN('Dataset'!H$5:H$11))/(MAX('Dataset'!H$5:H$11)-MIN('Dataset'!H$5:H$11))),'Dataset'!H11) -> 0 | H11: =IF('Dataset'!I$12=1,IF(MAX('Dataset'!I$5:I$11)=MIN('Dataset'!I$5:I$11),0,('Dataset'!I11-MIN('Dataset'!I$5:I$11))/(MAX('Dataset'!I$5:I$11)-MIN('Dataset'!I$5:I$11))),'Dataset'!I11) -> 2 | I11: =IF('Dataset'!J$12=1,IF(MAX('Dataset'!J$5:J$11)=MIN('Dataset'!J$5:J$11),0,('Dataset'!J11-MIN('Dataset'!J$5:J$11))/(MAX('Dataset'!J$5:J$11)-MIN('Dataset'!J$5:J$11))),'Dataset'!J11) -> 0.87037037 | ... N11: =IF('Dataset'!O$12=1,IF(MAX('Dataset'!O$5:O$11)=MIN('Dataset'!O$5:O$11),0,('Dataset'!O11-MIN('Dataset'!O$5:O$11))/(MAX('Dataset'!O$5:O$11)-MIN('Dataset'!O$5:O$11))),'Dataset'!O11) -> 3 | O11: ='Dataset'!P11 -> 1
A12: Type | B12: ='Dataset'!C$12 -> 1 | C12: ='Dataset'!D$12 -> 0 | D12: ='Dataset'!E$12 -> 0 | E12: ='Dataset'!F$12 -> 1 | F12: ='Dataset'!G$12 -> 1 | G12: ='Dataset'!H$12 -> 0 | H12: ='Dataset'!I$12 -> 0 | I12: ='Dataset'!J$12 -> 1 | ... N12: ='Dataset'!O$12 -> 0 | O12: 1 = I
A13: min | B13: =IF(B$12=1,MIN('Dataset'!C$5:C$11),"—") -> 41 | C13: =IF(C$12=1,MIN('Dataset'!D$5:D$11),"—") -> — | D13: =IF(D$12=1,MIN('Dataset'!E$5:E$11),"—") -> — | E13: =IF(E$12=1,MIN('Dataset'!F$5:F$11),"—") -> 130 | F13: =IF(F$12=1,MIN('Dataset'!G$5:G$11),"—") -> 203 | G13: =IF(G$12=1,MIN('Dataset'!H$5:H$11),"—") -> — | H13: =IF(H$12=1,MIN('Dataset'!I$5:I$11),"—") -> — | I13: =IF(I$12=1,MIN('Dataset'!J$5:J$11),"—") -> 109 | ... N13: =IF(N$12=1,MIN('Dataset'!O$5:O$11),"—") -> —
A14: max | B14: =IF(B$12=1,MAX('Dataset'!C$5:C$11),"—") -> 70 | C14: =IF(C$12=1,MAX('Dataset'!D$5:D$11),"—") -> — | D14: =IF(D$12=1,MAX('Dataset'!E$5:E$11),"—") -> — | E14: =IF(E$12=1,MAX('Dataset'!F$5:F$11),"—") -> 156 | F14: =IF(F$12=1,MAX('Dataset'!G$5:G$11),"—") -> 407 | G14: =IF(G$12=1,MAX('Dataset'!H$5:H$11),"—") -> — | H14: =IF(H$12=1,MAX('Dataset'!I$5:I$11),"—") -> — | I14: =IF(I$12=1,MAX('Dataset'!J$5:J$11),"—") -> 163 | ... N14: =IF(N$12=1,MAX('Dataset'!O$5:O$11),"—") -> —
A16: Type 1 = quantitative (set I): rescaled with the fractional-linear (min–max) transform; min and max are taken over the selected objects S₁ … S₇.
A17: Type 0 = nominal (set J): the code is kept, because the metric only asks whether two codes are equal.

Sheet Zhuravlev Distances
A1: Step 0 · Pairwise Zhuravlev distances ρ = ρ_I + ρ_J for all objects (row = Sᵢ, column = Sⱼ)
A3: ρ(Sᵢ, Sⱼ) · Zhuravlev distance = quantitative part + nominal part
A4: ρ | B4: S₁ | C4: S₂ | D4: S₃ | E4: S₄ | F4: S₅ | G4: S₆ | H4: S₇
A5: S₁ | B5: =ROUND(B15+B25,10) -> 0 | C5: =ROUND(C15+C25,10) -> 4.6606101 | D5: =ROUND(D15+D25,10) -> 5.6070806 | E5: =ROUND(E15+E25,10) -> 6.6272117 | F5: =ROUND(F15+F25,10) -> 4.8565209 | G5: =ROUND(G15+G25,10) -> 6.801567 | H5: =ROUND(H15+H25,10) -> 5.8897936
A6: S₂ | B6: =ROUND(B16+B26,10) -> 4.6606101 | C6: =ROUND(C16+C26,10) -> 0 | D6: =ROUND(D16+D26,10) -> 7.4699699 | E6: =ROUND(E16+E26,10) -> 6.3691658 | F6: =ROUND(F16+F26,10) -> 6.1040892 | G6: =ROUND(G16+G26,10) -> 8.7429512 | H6: =ROUND(H16+H26,10) -> 7.7855938
A7: S₃ | B7: =ROUND(B17+B27,10) -> 5.6070806 | C7: =ROUND(C17+C27,10) -> 7.4699699 | D7: =ROUND(D17+D27,10) -> 0 | E7: =ROUND(E17+E27,10) -> 6.217567 | F7: =ROUND(F17+F27,10) -> 7.3117497 | G7: =ROUND(G17+G27,10) -> 5.2172784 | H7: =ROUND(H17+H27,10) -> 2.7849754
A8: S₄ | B8: =ROUND(B18+B28,10) -> 6.6272117 | C8: =ROUND(C18+C28,10) -> 6.3691658 | D8: =ROUND(D18+D28,10) -> 6.217567 | E8: =ROUND(E18+E28,10) -> 0 | F8: =ROUND(F18+F28,10) -> 7.8491222 | G8: =ROUND(G18+G28,10) -> 3.7071188 | H8: =ROUND(H18+H28,10) -> 3.9109814
A9: S₅ | B9: =ROUND(B19+B29,10) -> 4.8565209 | C9: =ROUND(C19+C29,10) -> 6.1040892 | D9: =ROUND(D19+D29,10) -> 7.3117497 | E9: =ROUND(E19+E29,10) -> 7.8491222 | F9: =ROUND(F19+F29,10) -> 0 | G9: =ROUND(G19+G29,10) -> 9.0234774 | H9: =ROUND(H19+H29,10) -> 7.111704
A10: S₆ | B10: =ROUND(B20+B30,10) -> 6.801567 | C10: =ROUND(C20+C30,10) -> 8.7429512 | D10: =ROUND(D20+D30,10) -> 5.2172784 | E10: =ROUND(E20+E30,10) -> 3.7071188 | F10: =ROUND(F20+F30,10) -> 9.0234774 | G10: =ROUND(G20+G30,10) -> 0 | H10: =ROUND(H20+H30,10) -> 5.0314315
A11: S₇ | B11: =ROUND(B21+B31,10) -> 5.8897936 | C11: =ROUND(C21+C31,10) -> 7.7855938 | D11: =ROUND(D21+D31,10) -> 2.7849754 | E11: =ROUND(E21+E31,10) -> 3.9109814 | F11: =ROUND(F21+F31,10) -> 7.111704 | G11: =ROUND(G21+G31,10) -> 5.0314315 | H11: =ROUND(H21+H31,10) -> 0
A13: ρ_I · quantitative part Σ(j∈I) |x′ⱼ − y′ⱼ| (Step 0 values)
A14: ρ_I | B14: S₁ | C14: S₂ | D14: S₃ | E14: S₄ | F14: S₅ | G14: S₆ | H14: S₇
A15: S₁ | B15: =ROUND(SUMPRODUCT('Dataset'!$C$12:$O$12,ABS('Normalized Dataset'!$B$5:$N$5-'Normalized Dataset'!$B$5:$N$5)),10) -> 0 | C15: =ROUND(SUMPRODUCT('Dataset'!$C$12:$O$12,ABS('Normalized Dataset'!$B$5:$N$5-'Normalized Dataset'!$B$6:$N$6)),10) -> 2.6606101 | D15: =ROUND(SUMPRODUCT('Dataset'!$C$12:$O$12,ABS('Normalized Dataset'!$B$5:$N$5-'Normalized Dataset'!$B$7:$N$7)),10) -> 3.6070806 | E15: =ROUND(SUMPRODUCT('Dataset'!$C$12:$O$12,ABS('Normalized Dataset'!$B$5:$N$5-'Normalized Dataset'!$B$8:$N$8)),10) -> 3.6272117 | F15: =ROUND(SUMPRODUCT('Dataset'!$C$12:$O$12,ABS('Normalized Dataset'!$B$5:$N$5-'Normalized Dataset'!$B$9:$N$9)),10) -> 0.85652092 | G15: =ROUND(SUMPRODUCT('Dataset'!$C$12:$O$12,ABS('Normalized Dataset'!$B$5:$N$5-'Normalized Dataset'!$B$10:$N$10)),10) -> 3.801567 | H15: =ROUND(SUMPRODUCT('Dataset'!$C$12:$O$12,ABS('Normalized Dataset'!$B$5:$N$5-'Normalized Dataset'!$B$11:$N$11)),10) -> 3.8897936
A16: S₂ | B16: =ROUND(SUMPRODUCT('Dataset'!$C$12:$O$12,ABS('Normalized Dataset'!$B$6:$N$6-'Normalized Dataset'!$B$5:$N$5)),10) -> 2.6606101 | C16: =ROUND(SUMPRODUCT('Dataset'!$C$12:$O$12,ABS('Normalized Dataset'!$B$6:$N$6-'Normalized Dataset'!$B$6:$N$6)),10) -> 0 | D16: =ROUND(SUMPRODUCT('Dataset'!$C$12:$O$12,ABS('Normalized Dataset'!$B$6:$N$6-'Normalized Dataset'!$B$7:$N$7)),10) -> 3.4699699 | E16: =ROUND(SUMPRODUCT('Dataset'!$C$12:$O$12,ABS('Normalized Dataset'!$B$6:$N$6-'Normalized Dataset'!$B$8:$N$8)),10) -> 3.3691658 | F16: =ROUND(SUMPRODUCT('Dataset'!$C$12:$O$12,ABS('Normalized Dataset'!$B$6:$N$6-'Normalized Dataset'!$B$9:$N$9)),10) -> 2.1040892 | G16: =ROUND(SUMPRODUCT('Dataset'!$C$12:$O$12,ABS('Normalized Dataset'!$B$6:$N$6-'Normalized Dataset'!$B$10:$N$10)),10) -> 4.7429512 | H16: =ROUND(SUMPRODUCT('Dataset'!$C$12:$O$12,ABS('Normalized Dataset'!$B$6:$N$6-'Normalized Dataset'!$B$11:$N$11)),10) -> 3.7855938
A17: S₃ | B17: =ROUND(SUMPRODUCT('Dataset'!$C$12:$O$12,ABS('Normalized Dataset'!$B$7:$N$7-'Normalized Dataset'!$B$5:$N$5)),10) -> 3.6070806 | C17: =ROUND(SUMPRODUCT('Dataset'!$C$12:$O$12,ABS('Normalized Dataset'!$B$7:$N$7-'Normalized Dataset'!$B$6:$N$6)),10) -> 3.4699699 | D17: =ROUND(SUMPRODUCT('Dataset'!$C$12:$O$12,ABS('Normalized Dataset'!$B$7:$N$7-'Normalized Dataset'!$B$7:$N$7)),10) -> 0 | E17: =ROUND(SUMPRODUCT('Dataset'!$C$12:$O$12,ABS('Normalized Dataset'!$B$7:$N$7-'Normalized Dataset'!$B$8:$N$8)),10) -> 2.217567 | F17: =ROUND(SUMPRODUCT('Dataset'!$C$12:$O$12,ABS('Normalized Dataset'!$B$7:$N$7-'Normalized Dataset'!$B$9:$N$9)),10) -> 3.3117497 | G17: =ROUND(SUMPRODUCT('Dataset'!$C$12:$O$12,ABS('Normalized Dataset'!$B$7:$N$7-'Normalized Dataset'!$B$10:$N$10)),10) -> 2.2172784 | H17: =ROUND(SUMPRODUCT('Dataset'!$C$12:$O$12,ABS('Normalized Dataset'!$B$7:$N$7-'Normalized Dataset'!$B$11:$N$11)),10) -> 1.7849754
A18: S₄ | B18: =ROUND(SUMPRODUCT('Dataset'!$C$12:$O$12,ABS('Normalized Dataset'!$B$8:$N$8-'Normalized Dataset'!$B$5:$N$5)),10) -> 3.6272117 | C18: =ROUND(SUMPRODUCT('Dataset'!$C$12:$O$12,ABS('Normalized Dataset'!$B$8:$N$8-'Normalized Dataset'!$B$6:$N$6)),10) -> 3.3691658 | D18: =ROUND(SUMPRODUCT('Dataset'!$C$12:$O$12,ABS('Normalized Dataset'!$B$8:$N$8-'Normalized Dataset'!$B$7:$N$7)),10) -> 2.217567 | E18: =ROUND(SUMPRODUCT('Dataset'!$C$12:$O$12,ABS('Normalized Dataset'!$B$8:$N$8-'Normalized Dataset'!$B$8:$N$8)),10) -> 0 | F18: =ROUND(SUMPRODUCT('Dataset'!$C$12:$O$12,ABS('Normalized Dataset'!$B$8:$N$8-'Normalized Dataset'!$B$9:$N$9)),10) -> 2.8491222 | G18: =ROUND(SUMPRODUCT('Dataset'!$C$12:$O$12,ABS('Normalized Dataset'!$B$8:$N$8-'Normalized Dataset'!$B$10:$N$10)),10) -> 1.7071188 | H18: =ROUND(SUMPRODUCT('Dataset'!$C$12:$O$12,ABS('Normalized Dataset'!$B$8:$N$8-'Normalized Dataset'!$B$11:$N$11)),10) -> 0.91098137
A19: S₅ | B19: =ROUND(SUMPRODUCT('Dataset'!$C$12:$O$12,ABS('Normalized Dataset'!$B$9:$N$9-'Normalized Dataset'!$B$5:$N$5)),10) -> 0.85652092 | C19: =ROUND(SUMPRODUCT('Dataset'!$C$12:$O$12,ABS('Normalized Dataset'!$B$9:$N$9-'Normalized Dataset'!$B$6:$N$6)),10) -> 2.1040892 | D19: =ROUND(SUMPRODUCT('Dataset'!$C$12:$O$12,ABS('Normalized Dataset'!$B$9:$N$9-'Normalized Dataset'!$B$7:$N$7)),10) -> 3.3117497 | E19: =ROUND(SUMPRODUCT('Dataset'!$C$12:$O$12,ABS('Normalized Dataset'!$B$9:$N$9-'Normalized Dataset'!$B$8:$N$8)),10) -> 2.8491222 | F19: =ROUND(SUMPRODUCT('Dataset'!$C$12:$O$12,ABS('Normalized Dataset'!$B$9:$N$9-'Normalized Dataset'!$B$9:$N$9)),10) -> 0 | G19: =ROUND(SUMPRODUCT('Dataset'!$C$12:$O$12,ABS('Normalized Dataset'!$B$9:$N$9-'Normalized Dataset'!$B$10:$N$10)),10) -> 3.0234774 | H19: =ROUND(SUMPRODUCT('Dataset'!$C$12:$O$12,ABS('Normalized Dataset'!$B$9:$N$9-'Normalized Dataset'!$B$11:$N$11)),10) -> 3.111704
A20: S₆ | B20: =ROUND(SUMPRODUCT('Dataset'!$C$12:$O$12,ABS('Normalized Dataset'!$B$10:$N$10-'Normalized Dataset'!$B$5:$N$5)),10) -> 3.801567 | C20: =ROUND(SUMPRODUCT('Dataset'!$C$12:$O$12,ABS('Normalized Dataset'!$B$10:$N$10-'Normalized Dataset'!$B$6:$N$6)),10) -> 4.7429512 | D20: =ROUND(SUMPRODUCT('Dataset'!$C$12:$O$12,ABS('Normalized Dataset'!$B$10:$N$10-'Normalized Dataset'!$B$7:$N$7)),10) -> 2.2172784 | E20: =ROUND(SUMPRODUCT('Dataset'!$C$12:$O$12,ABS('Normalized Dataset'!$B$10:$N$10-'Normalized Dataset'!$B$8:$N$8)),10) -> 1.7071188 | F20: =ROUND(SUMPRODUCT('Dataset'!$C$12:$O$12,ABS('Normalized Dataset'!$B$10:$N$10-'Normalized Dataset'!$B$9:$N$9)),10) -> 3.0234774 | G20: =ROUND(SUMPRODUCT('Dataset'!$C$12:$O$12,ABS('Normalized Dataset'!$B$10:$N$10-'Normalized Dataset'!$B$10:$N$10)),10) -> 0 | H20: =ROUND(SUMPRODUCT('Dataset'!$C$12:$O$12,ABS('Normalized Dataset'!$B$10:$N$10-'Normalized Dataset'!$B$11:$N$11)),10) -> 1.0314315
A21: S₇ | B21: =ROUND(SUMPRODUCT('Dataset'!$C$12:$O$12,ABS('Normalized Dataset'!$B$11:$N$11-'Normalized Dataset'!$B$5:$N$5)),10) -> 3.8897936 | C21: =ROUND(SUMPRODUCT('Dataset'!$C$12:$O$12,ABS('Normalized Dataset'!$B$11:$N$11-'Normalized Dataset'!$B$6:$N$6)),10) -> 3.7855938 | D21: =ROUND(SUMPRODUCT('Dataset'!$C$12:$O$12,ABS('Normalized Dataset'!$B$11:$N$11-'Normalized Dataset'!$B$7:$N$7)),10) -> 1.7849754 | E21: =ROUND(SUMPRODUCT('Dataset'!$C$12:$O$12,ABS('Normalized Dataset'!$B$11:$N$11-'Normalized Dataset'!$B$8:$N$8)),10) -> 0.91098137 | F21: =ROUND(SUMPRODUCT('Dataset'!$C$12:$O$12,ABS('Normalized Dataset'!$B$11:$N$11-'Normalized Dataset'!$B$9:$N$9)),10) -> 3.111704 | G21: =ROUND(SUMPRODUCT('Dataset'!$C$12:$O$12,ABS('Normalized Dataset'!$B$11:$N$11-'Normalized Dataset'!$B$10:$N$10)),10) -> 1.0314315 | H21: =ROUND(SUMPRODUCT('Dataset'!$C$12:$O$12,ABS('Normalized Dataset'!$B$11:$N$11-'Normalized Dataset'!$B$11:$N$11)),10) -> 0
A23: ρ_J · nominal part Σ(j∈J) [xⱼ ≠ yⱼ] (number of nominal features with different codes)
A24: ρ_J | B24: S₁ | C24: S₂ | D24: S₃ | E24: S₄ | F24: S₅ | G24: S₆ | H24: S₇
A25: S₁ | B25: =SUMPRODUCT((1-'Dataset'!$C$12:$O$12)*('Dataset'!$C$5:$O$5<>'Dataset'!$C$5:$O$5)) -> 0 | C25: =SUMPRODUCT((1-'Dataset'!$C$12:$O$12)*('Dataset'!$C$5:$O$5<>'Dataset'!$C$6:$O$6)) -> 2 | D25: =SUMPRODUCT((1-'Dataset'!$C$12:$O$12)*('Dataset'!$C$5:$O$5<>'Dataset'!$C$7:$O$7)) -> 2 | E25: =SUMPRODUCT((1-'Dataset'!$C$12:$O$12)*('Dataset'!$C$5:$O$5<>'Dataset'!$C$8:$O$8)) -> 3 | F25: =SUMPRODUCT((1-'Dataset'!$C$12:$O$12)*('Dataset'!$C$5:$O$5<>'Dataset'!$C$9:$O$9)) -> 4 | G25: =SUMPRODUCT((1-'Dataset'!$C$12:$O$12)*('Dataset'!$C$5:$O$5<>'Dataset'!$C$10:$O$10)) -> 3 | H25: =SUMPRODUCT((1-'Dataset'!$C$12:$O$12)*('Dataset'!$C$5:$O$5<>'Dataset'!$C$11:$O$11)) -> 2
A26: S₂ | B26: =SUMPRODUCT((1-'Dataset'!$C$12:$O$12)*('Dataset'!$C$6:$O$6<>'Dataset'!$C$5:$O$5)) -> 2 | C26: =SUMPRODUCT((1-'Dataset'!$C$12:$O$12)*('Dataset'!$C$6:$O$6<>'Dataset'!$C$6:$O$6)) -> 0 | D26: =SUMPRODUCT((1-'Dataset'!$C$12:$O$12)*('Dataset'!$C$6:$O$6<>'Dataset'!$C$7:$O$7)) -> 4 | E26: =SUMPRODUCT((1-'Dataset'!$C$12:$O$12)*('Dataset'!$C$6:$O$6<>'Dataset'!$C$8:$O$8)) -> 3 | F26: =SUMPRODUCT((1-'Dataset'!$C$12:$O$12)*('Dataset'!$C$6:$O$6<>'Dataset'!$C$9:$O$9)) -> 4 | G26: =SUMPRODUCT((1-'Dataset'!$C$12:$O$12)*('Dataset'!$C$6:$O$6<>'Dataset'!$C$10:$O$10)) -> 4 | H26: =SUMPRODUCT((1-'Dataset'!$C$12:$O$12)*('Dataset'!$C$6:$O$6<>'Dataset'!$C$11:$O$11)) -> 4
A27: S₃ | B27: =SUMPRODUCT((1-'Dataset'!$C$12:$O$12)*('Dataset'!$C$7:$O$7<>'Dataset'!$C$5:$O$5)) -> 2 | C27: =SUMPRODUCT((1-'Dataset'!$C$12:$O$12)*('Dataset'!$C$7:$O$7<>'Dataset'!$C$6:$O$6)) -> 4 | D27: =SUMPRODUCT((1-'Dataset'!$C$12:$O$12)*('Dataset'!$C$7:$O$7<>'Dataset'!$C$7:$O$7)) -> 0 | E27: =SUMPRODUCT((1-'Dataset'!$C$12:$O$12)*('Dataset'!$C$7:$O$7<>'Dataset'!$C$8:$O$8)) -> 4 | F27: =SUMPRODUCT((1-'Dataset'!$C$12:$O$12)*('Dataset'!$C$7:$O$7<>'Dataset'!$C$9:$O$9)) -> 4 | G27: =SUMPRODUCT((1-'Dataset'!$C$12:$O$12)*('Dataset'!$C$7:$O$7<>'Dataset'!$C$10:$O$10)) -> 3 | H27: =SUMPRODUCT((1-'Dataset'!$C$12:$O$12)*('Dataset'!$C$7:$O$7<>'Dataset'!$C$11:$O$11)) -> 1
A28: S₄ | B28: =SUMPRODUCT((1-'Dataset'!$C$12:$O$12)*('Dataset'!$C$8:$O$8<>'Dataset'!$C$5:$O$5)) -> 3 | C28: =SUMPRODUCT((1-'Dataset'!$C$12:$O$12)*('Dataset'!$C$8:$O$8<>'Dataset'!$C$6:$O$6)) -> 3 | D28: =SUMPRODUCT((1-'Dataset'!$C$12:$O$12)*('Dataset'!$C$8:$O$8<>'Dataset'!$C$7:$O$7)) -> 4 | E28: =SUMPRODUCT((1-'Dataset'!$C$12:$O$12)*('Dataset'!$C$8:$O$8<>'Dataset'!$C$8:$O$8)) -> 0 | F28: =SUMPRODUCT((1-'Dataset'!$C$12:$O$12)*('Dataset'!$C$8:$O$8<>'Dataset'!$C$9:$O$9)) -> 5 | G28: =SUMPRODUCT((1-'Dataset'!$C$12:$O$12)*('Dataset'!$C$8:$O$8<>'Dataset'!$C$10:$O$10)) -> 2 | H28: =SUMPRODUCT((1-'Dataset'!$C$12:$O$12)*('Dataset'!$C$8:$O$8<>'Dataset'!$C$11:$O$11)) -> 3
A29: S₅ | B29: =SUMPRODUCT((1-'Dataset'!$C$12:$O$12)*('Dataset'!$C$9:$O$9<>'Dataset'!$C$5:$O$5)) -> 4 | C29: =SUMPRODUCT((1-'Dataset'!$C$12:$O$12)*('Dataset'!$C$9:$O$9<>'Dataset'!$C$6:$O$6)) -> 4 | D29: =SUMPRODUCT((1-'Dataset'!$C$12:$O$12)*('Dataset'!$C$9:$O$9<>'Dataset'!$C$7:$O$7)) -> 4 | E29: =SUMPRODUCT((1-'Dataset'!$C$12:$O$12)*('Dataset'!$C$9:$O$9<>'Dataset'!$C$8:$O$8)) -> 5 | F29: =SUMPRODUCT((1-'Dataset'!$C$12:$O$12)*('Dataset'!$C$9:$O$9<>'Dataset'!$C$9:$O$9)) -> 0 | G29: =SUMPRODUCT((1-'Dataset'!$C$12:$O$12)*('Dataset'!$C$9:$O$9<>'Dataset'!$C$10:$O$10)) -> 6 | H29: =SUMPRODUCT((1-'Dataset'!$C$12:$O$12)*('Dataset'!$C$9:$O$9<>'Dataset'!$C$11:$O$11)) -> 4
A30: S₆ | B30: =SUMPRODUCT((1-'Dataset'!$C$12:$O$12)*('Dataset'!$C$10:$O$10<>'Dataset'!$C$5:$O$5)) -> 3 | C30: =SUMPRODUCT((1-'Dataset'!$C$12:$O$12)*('Dataset'!$C$10:$O$10<>'Dataset'!$C$6:$O$6)) -> 4 | D30: =SUMPRODUCT((1-'Dataset'!$C$12:$O$12)*('Dataset'!$C$10:$O$10<>'Dataset'!$C$7:$O$7)) -> 3 | E30: =SUMPRODUCT((1-'Dataset'!$C$12:$O$12)*('Dataset'!$C$10:$O$10<>'Dataset'!$C$8:$O$8)) -> 2 | F30: =SUMPRODUCT((1-'Dataset'!$C$12:$O$12)*('Dataset'!$C$10:$O$10<>'Dataset'!$C$9:$O$9)) -> 6 | G30: =SUMPRODUCT((1-'Dataset'!$C$12:$O$12)*('Dataset'!$C$10:$O$10<>'Dataset'!$C$10:$O$10)) -> 0 | H30: =SUMPRODUCT((1-'Dataset'!$C$12:$O$12)*('Dataset'!$C$10:$O$10<>'Dataset'!$C$11:$O$11)) -> 4
A31: S₇ | B31: =SUMPRODUCT((1-'Dataset'!$C$12:$O$12)*('Dataset'!$C$11:$O$11<>'Dataset'!$C$5:$O$5)) -> 2 | C31: =SUMPRODUCT((1-'Dataset'!$C$12:$O$12)*('Dataset'!$C$11:$O$11<>'Dataset'!$C$6:$O$6)) -> 4 | D31: =SUMPRODUCT((1-'Dataset'!$C$12:$O$12)*('Dataset'!$C$11:$O$11<>'Dataset'!$C$7:$O$7)) -> 1 | E31: =SUMPRODUCT((1-'Dataset'!$C$12:$O$12)*('Dataset'!$C$11:$O$11<>'Dataset'!$C$8:$O$8)) -> 3 | F31: =SUMPRODUCT((1-'Dataset'!$C$12:$O$12)*('Dataset'!$C$11:$O$11<>'Dataset'!$C$9:$O$9)) -> 4 | G31: =SUMPRODUCT((1-'Dataset'!$C$12:$O$12)*('Dataset'!$C$11:$O$11<>'Dataset'!$C$10:$O$10)) -> 4 | H31: =SUMPRODUCT((1-'Dataset'!$C$12:$O$12)*('Dataset'!$C$11:$O$11<>'Dataset'!$C$11:$O$11)) -> 0
A33: Every distance is rounded to 10 decimals, so that mathematically equal distances (e.g. r(S₁) = r(S₃) = ρ(S₁, S₃)) tie exactly.
A34: The diagonal (grey) is the distance of an object to itself; it is never a neighbour, but it explains why Sᵢ lies inside its own enemy sphere (0 < r(Sᵢ)).

Sheet Sorted Neighbors
A1: Step 0 · Sorted neighbours — nearest enemy r, k-th neighbour z, own-class objects inside the enemy sphere g
A3: Rank of Sⱼ in the neighbour list of Sᵢ (self excluded; equal ρ → smaller index first)
A4: Sᵢ \ Sⱼ | B4: S₁ | C4: S₂ | D4: S₃ | E4: S₄ | F4: S₅ | G4: S₆ | H4: S₇
A5: S₁ | B5: — | C5: =1+SUMPRODUCT(('Zhuravlev Distances'!$B$5:$H$5<'Zhuravlev Distances'!C$5)*(COLUMN('Zhuravlev Distances'!$B$5:$H$5)<>COLUMN('Zhuravlev Distances'!B$5)))+SUMPRODUCT(('Zhuravlev Distances'!$B$5:$H$5='Zhuravlev Distances'!C$5)*(COLUMN('Zhuravlev Distances'!$B$5:$H$5)<COLUMN('Zhuravlev Distances'!C$5))*(COLUMN('Zhuravlev Distances'!$B$5:$H$5)<>COLUMN('Zhuravlev Distances'!B$5))) -> 1 | D5: =1+SUMPRODUCT(('Zhuravlev Distances'!$B$5:$H$5<'Zhuravlev Distances'!D$5)*(COLUMN('Zhuravlev Distances'!$B$5:$H$5)<>COLUMN('Zhuravlev Distances'!B$5)))+SUMPRODUCT(('Zhuravlev Distances'!$B$5:$H$5='Zhuravlev Distances'!D$5)*(COLUMN('Zhuravlev Distances'!$B$5:$H$5)<COLUMN('Zhuravlev Distances'!D$5))*(COLUMN('Zhuravlev Distances'!$B$5:$H$5)<>COLUMN('Zhuravlev Distances'!B$5))) -> 3 | E5: =1+SUMPRODUCT(('Zhuravlev Distances'!$B$5:$H$5<'Zhuravlev Distances'!E$5)*(COLUMN('Zhuravlev Distances'!$B$5:$H$5)<>COLUMN('Zhuravlev Distances'!B$5)))+SUMPRODUCT(('Zhuravlev Distances'!$B$5:$H$5='Zhuravlev Distances'!E$5)*(COLUMN('Zhuravlev Distances'!$B$5:$H$5)<COLUMN('Zhuravlev Distances'!E$5))*(COLUMN('Zhuravlev Distances'!$B$5:$H$5)<>COLUMN('Zhuravlev Distances'!B$5))) -> 5 | F5: =1+SUMPRODUCT(('Zhuravlev Distances'!$B$5:$H$5<'Zhuravlev Distances'!F$5)*(COLUMN('Zhuravlev Distances'!$B$5:$H$5)<>COLUMN('Zhuravlev Distances'!B$5)))+SUMPRODUCT(('Zhuravlev Distances'!$B$5:$H$5='Zhuravlev Distances'!F$5)*(COLUMN('Zhuravlev Distances'!$B$5:$H$5)<COLUMN('Zhuravlev Distances'!F$5))*(COLUMN('Zhuravlev Distances'!$B$5:$H$5)<>COLUMN('Zhuravlev Distances'!B$5))) -> 2 | G5: =1+SUMPRODUCT(('Zhuravlev Distances'!$B$5:$H$5<'Zhuravlev Distances'!G$5)*(COLUMN('Zhuravlev Distances'!$B$5:$H$5)<>COLUMN('Zhuravlev Distances'!B$5)))+SUMPRODUCT(('Zhuravlev Distances'!$B$5:$H$5='Zhuravlev Distances'!G$5)*(COLUMN('Zhuravlev Distances'!$B$5:$H$5)<COLUMN('Zhuravlev Distances'!G$5))*(COLUMN('Zhuravlev Distances'!$B$5:$H$5)<>COLUMN('Zhuravlev Distances'!B$5))) -> 6 | H5: =1+SUMPRODUCT(('Zhuravlev Distances'!$B$5:$H$5<'Zhuravlev Distances'!H$5)*(COLUMN('Zhuravlev Distances'!$B$5:$H$5)<>COLUMN('Zhuravlev Distances'!B$5)))+SUMPRODUCT(('Zhuravlev Distances'!$B$5:$H$5='Zhuravlev Distances'!H$5)*(COLUMN('Zhuravlev Distances'!$B$5:$H$5)<COLUMN('Zhuravlev Distances'!H$5))*(COLUMN('Zhuravlev Distances'!$B$5:$H$5)<>COLUMN('Zhuravlev Distances'!B$5))) -> 4
